Workbook
Name Slicer_Player: #N/A

Sheet raw_data
A1: Sr.No | B1: Player | C1: Span | D1: Mat | E1: Inns | F1: NO | G1: Runs | H1: HS | I1: Ave | J1: 100 | K1: 50 | L1: 0 | M1: Not Out % | N1: Runs Per Innings | O1: 50+ Scores | P1: Century Contribution % | Q1: HS Numeric
A2: 1 | B2: SR Tendulkar (INDIA) | C2: 1989-2013 | D2: 200 | E2: 329 | F2: 33 | G2: 15921 | H2: 248* | I2: 53.78 | J2: 51 | K2: 68 | L2: 14 | M2: =IF(E2=0,0,F2/E2) -> 0.10030395 | N2: =IF(E2=0,0,G2/E2) -> 48.392097 | O2: =J2+K2 -> 119 | P2: =IF(O2=0,0,J2/O2) -> 0.42857143 | Q2: =VALUE(SUBSTITUTE(H2,"*","")) -> 248
A3: 2 | B3: RT Ponting (AUS) | C3: 1995-2012 | D3: 168 | E3: 287 | F3: 29 | G3: 13378 | H3: 257 | I3: 51.85 | J3: 41 | K3: 62 | L3: 17 | M3: =IF(E3=0,0,F3/E3) -> 0.1010453 | N3: =IF(E3=0,0,G3/E3) -> 46.61324 | O3: =J3+K3 -> 103 | P3: =IF(O3=0,0,J3/O3) -> 0.39805825 | Q3: =VALUE(SUBSTITUTE(H3,"*","")) -> 257
A4: 3 | B4: JH Kallis (ICC/SA) | C4: 1995-2013 | D4: 166 | E4: 280 | F4: 40 | G4: 13289 | H4: 224 | I4: 55.37 | J4: 45 | K4: 58 | L4: 16 | M4: =IF(E4=0,0,F4/E4) -> 0.14285714 | N4: =IF(E4=0,0,G4/E4) -> 47.460714 | O4: =J4+K4 -> 103 | P4: =IF(O4=0,0,J4/O4) -> 0.4368932 | Q4: =VALUE(SUBSTITUTE(H4,"*","")) -> 224
A5: 4 | B5: R Dravid (ICC/INDIA) | C5: 1996-2012 | D5: 164 | E5: 286 | F5: 32 | G5: 13288 | H5: 270 | I5: 52.31 | J5: 36 | K5: 63 | L5: 8 | M5: =IF(E5=0,0,F5/E5) -> 0.11188811 | N5: =IF(E5=0,0,G5/E5) -> 46.461538 | O5: =J5+K5 -> 99 | P5: =IF(O5=0,0,J5/O5) -> 0.36363636 | Q5: =VALUE(SUBSTITUTE(H5,"*","")) -> 270
A6: 5 | B6: AN Cook (ENG) | C6: 2006-2018 | D6: 161 | E6: 291 | F6: 16 | G6: 12472 | H6: 294 | I6: 45.35 | J6: 33 | K6: 57 | L6: 9 | M6: =IF(E6=0,0,F6/E6) -> 0.054982818 | N6: =IF(E6=0,0,G6/E6) -> 42.859107 | O6: =J6+K6 -> 90 | P6: =IF(O6=0,0,J6/O6) -> 0.36666667 | Q6: =VALUE(SUBSTITUTE(H6,"*","")) -> 294
A7: 6 | B7: KC Sangakkara (SL) | C7: 2000-2015 | D7: 134 | E7: 233 | F7: 17 | G7: 12400 | H7: 319 | I7: 57.4 | J7: 38 | K7: 52 | L7: 11 | M7: =IF(E7=0,0,F7/E7) -> 0.072961373 | N7: =IF(E7=0,0,G7/E7) -> 53.218884 | O7: =J7+K7 -> 90 | P7: =IF(O7=0,0,J7/O7) -> 0.42222222 | Q7: =VALUE(SUBSTITUTE(H7,"*","")) -> 319
A8: 7 | B8: BC Lara (ICC/WI) | C8: 1990-2006 | D8: 131 | E8: 232 | F8: 6 | G8: 11953 | H8: 400* | I8: 52.88 | J8: 34 | K8: 48 | L8: 17 | M8: =IF(E8=0,0,F8/E8) -> 0.025862069 | N8: =IF(E8=0,0,G8/E8) -> 51.521552 | O8: =J8+K8 -> 82 | P8: =IF(O8=0,0,J8/O8) -> 0.41463415 | Q8: =VALUE(SUBSTITUTE(H8,"*","")) -> 400
A9: 8 | B9: S Chanderpaul (WI) | C9: 1994-2015 | D9: 164 | E9: 280 | F9: 49 | G9: 11867 | H9: 203* | I9: 51.37 | J9: 30 | K9: 66 | L9: 15 | M9: =IF(E9=0,0,F9/E9) -> 0.175 | N9: =IF(E9=0,0,G9/E9) -> 42.382143 | O9: =J9+K9 -> 96 | P9: =IF(O9=0,0,J9/O9) -> 0.3125 | Q9: =VALUE(SUBSTITUTE(H9,"*","")) -> 203
A10: 9 | B10: DPMD Jayawardene (SL) | C10: 1997-2014 | D10: 149 | E10: 252 | F10: 15 | G10: 11814 | H10: 374 | I10: 49.84 | J10: 34 | K10: 50 | L10: 15 | M10: =IF(E10=0,0,F10/E10) -> 0.05952381 | N10: =IF(E10=0,0,G10/E10) -> 46.880952 | O10: =J10+K10 -> 84 | P10: =IF(O10=0,0,J10/O10) -> 0.4047619 | Q10: =VALUE(SUBSTITUTE(H10,"*","")) -> 374
A11: 10 | B11: AR Border (AUS) | C11: 1978-1994 | D11: 156 | E11: 265 | F11: 44 | G11: 11174 | H11: 205 | I11: 50.56 | J11: 27 | K11: 63 | L11: 11 | M11: =IF(E11=0,0,F11/E11) -> 0.16603774 | N11: =IF(E11=0,0,G11/E11) -> 42.166038 | O11: =J11+K11 -> 90 | P11: =IF(O11=0,0,J11/O11) -> 0.3 | Q11: =VALUE(SUBSTITUTE(H11,"*","")) -> 205
A12: 11 | B12: SR Waugh (AUS) | C12: 1985-2004 | D12: 168 | E12: 260 | F12: 46 | G12: 10927 | H12: 200 | I12: 51.06 | J12: 32 | K12: 50 | L12: 22 | M12: =IF(E12=0,0,F12/E12) -> 0.17692308 | N12: =IF(E12=0,0,G12/E12) -> 42.026923 | O12: =J12+K12 -> 82 | P12: =IF(O12=0,0,J12/O12) -> 0.3902439 | Q12: =VALUE(SUBSTITUTE(H12,"*","")) -> 200
A13: 12 | B13: SM Gavaskar (INDIA) | C13: 1971-1987 | D13: 125 | E13: 214 | F13: 16 | G13: 10122 | H13: 236* | I13: 51.12 | J13: 34 | K13: 45 | L13: 12 | M13: =IF(E13=0,0,F13/E13) -> 0.074766355 | N13: =IF(E13=0,0,G13/E13) -> 47.299065 | O13: =J13+K13 -> 79 | P13: =IF(O13=0,0,J13/O13) -> 0.43037975 | Q13: =VALUE(SUBSTITUTE(H13,"*","")) -> 236
A14: 13 | B14: Younis Khan (PAK) | C14: 2000-2017 | D14: 118 | E14: 213 | F14: 19 | G14: 10099 | H14: 313 | I14: 52.05 | J14: 34 | K14: 33 | L14: 19 | M14: =IF(E14=0,0,F14/E14) -> 0.089201878 | N14: =IF(E14=0,0,G14/E14) -> 47.413146 | O14: =J14+K14 -> 67 | P14: =IF(O14=0,0,J14/O14) -> 0.50746269 | Q14: =VALUE(SUBSTITUTE(H14,"*","")) -> 313
A15: 14 | B15: JE Root (ENG) | C15: 2012-2021 | D15: 111* | E15: 202 | F15: 15 | G15: 9367 | H15: 254 | I15: 50.09 | J15: 23 | K15: 51 | L15: 9 | M15: =IF(E15=0,0,F15/E15) -> 0.074257426 | N15: =IF(E15=0,0,G15/E15) -> 46.371287 | O15: =J15+K15 -> 74 | P15: =IF(O15=0,0,J15/O15) -> 0.31081081 | Q15: =VALUE(SUBSTITUTE(H15,"*","")) -> 254
A16: 15 | B16: HM Amla (SA) | C16: 2004-2019 | D16: 124 | E16: 215 | F16: 16 | G16: 9282 | H16: 311* | I16: 46.64 | J16: 28 | K16: 41 | L16: 13 | M16: =IF(E16=0,0,F16/E16) -> 0.074418605 | N16: =IF(E16=0,0,G16/E16) -> 43.172093 | O16: =J16+K16 -> 69 | P16: =IF(O16=0,0,J16/O16) -> 0.4057971 | Q16: =VALUE(SUBSTITUTE(H16,"*","")) -> 311
A17: 16 | B17: GC Smith (ICC/SA) | C17: 2002-2014 | D17: 117 | E17: 205 | F17: 13 | G17: 9265 | H17: 277 | I17: 48.25 | J17: 27 | K17: 38 | L17: 11 | M17: =IF(E17=0,0,F17/E17) -> 0.063414634 | N17: =IF(E17=0,0,G17/E17) -> 45.195122 | O17: =J17+K17 -> 65 | P17: =IF(O17=0,0,J17/O17) -> 0.41538462 | Q17: =VALUE(SUBSTITUTE(H17,"*","")) -> 277
A18: 17 | B18: GA Gooch (ENG) | C18: 1975-1995 | D18: 118 | E18: 215 | F18: 6 | G18: 8900 | H18: 333 | I18: 42.58 | J18: 20 | K18: 46 | L18: 13 | M18: =IF(E18=0,0,F18/E18) -> 0.027906977 | N18: =IF(E18=0,0,G18/E18) -> 41.395349 | O18: =J18+K18 -> 66 | P18: =IF(O18=0,0,J18/O18) -> 0.3030303 | Q18: =VALUE(SUBSTITUTE(H18,"*","")) -> 333
A19: 18 | B19: Javed Miandad (PAK) | C19: 1976-1993 | D19: 124 | E19: 189 | F19: 21 | G19: 8832 | H19: 280* | I19: 52.57 | J19: 23 | K19: 43 | L19: 6 | M19: =IF(E19=0,0,F19/E19) -> 0.11111111 | N19: =IF(E19=0,0,G19/E19) -> 46.730159 | O19: =J19+K19 -> 66 | P19: =IF(O19=0,0,J19/O19) -> 0.34848485 | Q19: =VALUE(SUBSTITUTE(H19,"*","")) -> 280
A20: 19 | B20: Inzamam-ul-Haq (ICC/PAK) | C20: 1992-2007 | D20: 120 | E20: 200 | F20: 22 | G20: 8830 | H20: 329 | I20: 49.6 | J20: 25 | K20: 46 | L20: 15 | M20: =IF(E20=0,0,F20/E20) -> 0.11 | N20: =IF(E20=0,0,G20/E20) -> 44.15 | O20: =J20+K20 -> 71 | P20: =IF(O20=0,0,J20/O20) -> 0.35211268 | Q20: =VALUE(SUBSTITUTE(H20,"*","")) -> 329
A21: 20 | B21: VVS Laxman (INDIA) | C21: 1996-2012 | D21: 134 | E21: 225 | F21: 34 | G21: 8781 | H21: 281 | I21: 45.97 | J21: 17 | K21: 56 | L21: 14 | M21: =IF(E21=0,0,F21/E21) -> 0.15111111 | N21: =IF(E21=0,0,G21/E21) -> 39.026667 | O21: =J21+K21 -> 73 | P21: =IF(O21=0,0,J21/O21) -> 0.23287671 | Q21: =VALUE(SUBSTITUTE(H21,"*","")) -> 281
A22: 21 | B22: AB de Villiers (SA) | C22: 2004-2018 | D22: 114 | E22: 191 | F22: 18 | G22: 8765 | H22: 278* | I22: 50.66 | J22: 22 | K22: 46 | L22: 8 | M22: =IF(E22=0,0,F22/E22) -> 0.094240838 | N22: =IF(E22=0,0,G22/E22) -> 45.890052 | O22: =J22+K22 -> 68 | P22: =IF(O22=0,0,J22/O22) -> 0.32352941 | Q22: =VALUE(SUBSTITUTE(H22,"*","")) -> 278
A23: 22 | B23: MJ Clarke (AUS) | C23: 2004-2015 | D23: 115 | E23: 198 | F23: 22 | G23: 8643 | H23: 329* | I23: 49.1 | J23: 28 | K23: 27 | L23: 9 | M23: =IF(E23=0,0,F23/E23) -> 0.11111111 | N23: =IF(E23=0,0,G23/E23) -> 43.651515 | O23: =J23+K23 -> 55 | P23: =IF(O23=0,0,J23/O23) -> 0.50909091 | Q23: =VALUE(SUBSTITUTE(H23,"*","")) -> 329
A24: 23 | B24: ML Hayden (AUS) | C24: 1994-2009 | D24: 103 | E24: 184 | F24: 14 | G24: 8625 | H24: 380 | I24: 50.73 | J24: 30 | K24: 29 | L24: 14 | M24: =IF(E24=0,0,F24/E24) -> 0.076086957 | N24: =IF(E24=0,0,G24/E24) -> 46.875 | O24: =J24+K24 -> 59 | P24: =IF(O24=0,0,J24/O24) -> 0.50847458 | Q24: =VALUE(SUBSTITUTE(H24,"*","")) -> 380
A25: 24 | B25: V Sehwag (ICC/INDIA) | C25: 2001-2013 | D25: 104 | E25: 180 | F25: 6 | G25: 8586 | H25: 319 | I25: 49.34 | J25: 23 | K25: 32 | L25: 16 | M25: =IF(E25=0,0,F25/E25) -> 0.033333333 | N25: =IF(E25=0,0,G25/E25) -> 47.7 | O25: =J25+K25 -> 55 | P25: =IF(O25=0,0,J25/O25) -> 0.41818182 | Q25: =VALUE(SUBSTITUTE(H25,"*","")) -> 319
A26: 25 | B26: IVA Richards (WI) | C26: 1974-1991 | D26: 121 | E26: 182 | F26: 12 | G26: 8540 | H26: 291 | I26: 50.23 | J26: 24 | K26: 45 | L26: 10 | M26: =IF(E26=0,0,F26/E26) -> 0.065934066 | N26: =IF(E26=0,0,G26/E26) -> 46.923077 | O26: =J26+K26 -> 69 | P26: =IF(O26=0,0,J26/O26) -> 0.34782609 | Q26: =VALUE(SUBSTITUTE(H26,"*","")) -> 291
A27: 26 | B27: AJ Stewart (ENG) | C27: 1990-2003 | D27: 133 | E27: 235 | F27: 21 | G27: 8463 | H27: 190 | I27: 39.54 | J27: 15 | K27: 45 | L27: 14 | M27: =IF(E27=0,0,F27/E27) -> 0.089361702 | N27: =IF(E27=0,0,G27/E27) -> 36.012766 | O27: =J27+K27 -> 60 | P27: =IF(O27=0,0,J27/O27) -> 0.25 | Q27: =VALUE(SUBSTITUTE(H27,"*","")) -> 190
A28: 27 | B28: DI Gower (ENG) | C28: 1978-1992 | D28: 117 | E28: 204 | F28: 18 | G28: 8231 | H28: 215 | I28: 44.25 | J28: 18 | K28: 39 | L28: 7 | M28: =IF(E28=0,0,F28/E28) -> 0.088235294 | N28: =IF(E28=0,0,G28/E28) -> 40.348039 | O28: =J28+K28 -> 57 | P28: =IF(O28=0,0,J28/O28) -> 0.31578947 | Q28: =VALUE(SUBSTITUTE(H28,"*","")) -> 215
A29: 28 | B29: KP Pietersen (ENG) | C29: 2005-2014 | D29: 104 | E29: 181 | F29: 8 | G29: 8181 | H29: 227 | I29: 47.28 | J29: 23 | K29: 35 | L29: 10 | M29: =IF(E29=0,0,F29/E29) -> 0.044198895 | N29: =IF(E29=0,0,G29/E29) -> 45.198895 | O29: =J29+K29 -> 58 | P29: =IF(O29=0,0,J29/O29) -> 0.39655172 | Q29: =VALUE(SUBSTITUTE(H29,"*","")) -> 227
A30: 29 | B30: G Boycott (ENG) | C30: 1964-1982 | D30: 108 | E30: 193 | F30: 23 | G30: 8114 | H30: 246* | I30: 47.72 | J30: 22 | K30: 42 | L30: 10 | M30: =IF(E30=0,0,F30/E30) -> 0.11917098 | N30: =IF(E30=0,0,G30/E30) -> 42.041451 | O30: =J30+K30 -> 64 | P30: =IF(O30=0,0,J30/O30) -> 0.34375 | Q30: =VALUE(SUBSTITUTE(H30,"*","")) -> 246
A31: 30 | B31: GS Sobers (WI) | C31: 1954-1974 | D31: 93 | E31: 160 | F31: 21 | G31: 8032 | H31: 365* | I31: 57.78 | J31: 26 | K31: 30 | L31: 12 | M31: =IF(E31=0,0,F31/E31) -> 0.13125 | N31: =IF(E31=0,0,G31/E31) -> 50.2 | O31: =J31+K31 -> 56 | P31: =IF(O31=0,0,J31/O31) -> 0.46428571 | Q31: =VALUE(SUBSTITUTE(H31,"*","")) -> 365
A32: 31 | B32: ME Waugh (AUS) | C32: 1991-2002 | D32: 128 | E32: 209 | F32: 17 | G32: 8029 | H32: 153* | I32: 41.81 | J32: 20 | K32: 47 | L32: 19 | M32: =IF(E32=0,0,F32/E32) -> 0.081339713 | N32: =IF(E32=0,0,G32/E32) -> 38.416268 | O32: =J32+K32 -> 67 | P32: =IF(O32=0,0,J32/O32) -> 0.29850746 | Q32: =VALUE(SUBSTITUTE(H32,"*","")) -> 153
A33: 32 | B33: V Kohli (INDIA) | C33: 2011-2021 | D33: 97 | E33: 164 | F33: 10 | G33: 7801 | H33: 254* | I33: 50.65 | J33: 27 | K33: 27 | L33: 14 | M33: =IF(E33=0,0,F33/E33) -> 0.06097561 | N33: =IF(E33=0,0,G33/E33) -> 47.567073 | O33: =J33+K33 -> 54 | P33: =IF(O33=0,0,J33/O33) -> 0.5 | Q33: =VALUE(SUBSTITUTE(H33,"*","")) -> 254
A34: 33 | B34: MA Atherton (ENG) | C34: 1989-2001 | D34: 115 | E34: 212 | F34: 7 | G34: 7728 | H34: 185* | I34: 37.69 | J34: 16 | K34: 46 | L34: 20 | M34: =IF(E34=0,0,F34/E34) -> 0.033018868 | N34: =IF(E34=0,0,G34/E34) -> 36.45283 | O34: =J34+K34 -> 62 | P34: =IF(O34=0,0,J34/O34) -> 0.25806452 | Q34: =VALUE(SUBSTITUTE(H34,"*","")) -> 185
A35: 34 | B35: IR Bell (ENG) | C35: 2004-2015 | D35: 118 | E35: 205 | F35: 24 | G35: 7727 | H35: 235 | I35: 42.69 | J35: 22 | K35: 46 | L35: 14 | M35: =IF(E35=0,0,F35/E35) -> 0.11707317 | N35: =IF(E35=0,0,G35/E35) -> 37.692683 | O35: =J35+K35 -> 68 | P35: =IF(O35=0,0,J35/O35) -> 0.32352941 | Q35: =VALUE(SUBSTITUTE(H35,"*","")) -> 235
A36: 35 | B36: JL Langer (AUS) | C36: 1993-2007 | D36: 105 | E36: 182 | F36: 12 | G36: 7696 | H36: 250 | I36: 45.27 | J36: 23 | K36: 30 | L36: 11 | M36: =IF(E36=0,0,F36/E36) -> 0.065934066 | N36: =IF(E36=0,0,G36/E36) -> 42.285714 | O36: =J36+K36 -> 53 | P36: =IF(O36=0,0,J36/O36) -> 0.43396226 | Q36: =VALUE(SUBSTITUTE(H36,"*","")) -> 250
A37: 36 | B37: SPD Smith (AUS) | C37: 2010-2021 | D37: 79* | E37: 141 | F37: 18 | G37: 7625 | H37: 239 | I37: 61.99 | J37: 27 | K37: 32 | L37: 5 | M37: =IF(E37=0,0,F37/E37) -> 0.12765957 | N37: =IF(E37=0,0,G37/E37) -> 54.078014 | O37: =J37+K37 -> 59 | P37: =IF(O37=0,0,J37/O37) -> 0.45762712 | Q37: =VALUE(SUBSTITUTE(H37,"*","")) -> 239
A38: 37 | B38: MC Cowdrey (ENG) | C38: 1954-1975 | D38: 114 | E38: 188 | F38: 15 | G38: 7624 | H38: 182 | I38: 44.06 | J38: 22 | K38: 38 | L38: 9 | M38: =IF(E38=0,0,F38/E38) -> 0.079787234 | N38: =IF(E38=0,0,G38/E38) -> 40.553191 | O38: =J38+K38 -> 60 | P38: =IF(O38=0,0,J38/O38) -> 0.36666667 | Q38: =VALUE(SUBSTITUTE(H38,"*","")) -> 182
A39: 38 | B39: LRPL Taylor (NZ) | C39: 2007-2021 | D39: 110 | E39: 193 | F39: 24 | G39: 7584 | H39: 290 | I39: 44.87 | J39: 19 | K39: 35 | L39: 14 | M39: =IF(E39=0,0,F39/E39) -> 0.12435233 | N39: =IF(E39=0,0,G39/E39) -> 39.295337 | O39: =J39+K39 -> 54 | P39: =IF(O39=0,0,J39/O39) -> 0.35185185 | Q39: =VALUE(SUBSTITUTE(H39,"*","")) -> 290
A40: 39 | B40: CG Greenidge (WI) | C40: 1974-1991 | D40: 108 | E40: 185 | F40: 16 | G40: 7558 | H40: 226 | I40: 44.72 | J40: 19 | K40: 34 | L40: 11 | M40: =IF(E40=0,0,F40/E40) -> 0.086486486 | N40: =IF(E40=0,0,G40/E40) -> 40.854054 | O40: =J40+K40 -> 53 | P40: =IF(O40=0,0,J40/O40) -> 0.35849057 | Q40: =VALUE(SUBSTITUTE(H40,"*","")) -> 226
...

Sheet Pivot_Analysis

Sheet Top 10 Run Scorers
A3: Row Labels | B3: Sum of Runs
A4: SR Tendulkar (INDIA) | B4: 15921
A5: S Chanderpaul (WI) | B5: 11867
A6: RT Ponting (AUS) | B6: 13378
A7: R Dravid (ICC/INDIA) | B7: 13288
A8: KC Sangakkara (SL) | B8: 12400
A9: JH Kallis (ICC/SA) | B9: 13289
A10: DPMD Jayawardene (SL) | B10: 11814
A11: BC Lara (ICC/WI) | B11: 11953
A12: AR Border (AUS) | B12: 11174
A13: AN Cook (ENG) | B13: 12472
A14: Grand Total | B14: 127556

Sheet Top 10 Batting Average
A3: Row Labels | B3: Average of Ave
A4: DG Bradman (AUS) | B4: 99.94
A5: SPD Smith (AUS) | B5: 61.99
A6: KF Barrington (ENG) | B6: 58.67
A7: WR Hammond (ENG) | B7: 58.45
A8: GS Sobers (WI) | B8: 57.78
A9: KC Sangakkara (SL) | B9: 57.4
A10: JB Hobbs (ENG) | B10: 56.94
A11: L Hutton (ENG) | B11: 56.67
A12: JH Kallis (ICC/SA) | B12: 55.37
A13: GS Chappell (AUS) | B13: 53.86
A14: Grand Total | B14: 61.707

Sheet Top 10 Highest Individual Score
A3: Row Labels | B3: Sum of HS Numeric
A4: BC Lara (ICC/WI) | B4: 400
A5: ML Hayden (AUS) | B5: 380
A6: DPMD Jayawardene (SL) | B6: 374
A7: GS Sobers (WI) | B7: 365
A8: L Hutton (ENG) | B8: 364
A9: ST Jayasuriya (SL) | B9: 340
A10: WR Hammond (ENG) | B10: 336
A11: DA Warner (AUS) | B11: 335
A12: DG Bradman (AUS) | B12: 334
A13: MA Taylor (AUS) | B13: 334
A14: Grand Total | B14: 3562

Sheet Top 10 Century Makers
A1: Row Labels | B1: Sum of 100
A2: SR Tendulkar (INDIA) | B2: 51
A3: JH Kallis (ICC/SA) | B3: 45
A4: RT Ponting (AUS) | B4: 41
A5: KC Sangakkara (SL) | B5: 38
A6: R Dravid (ICC/INDIA) | B6: 36
A7: Younis Khan (PAK) | B7: 34
A8: BC Lara (ICC/WI) | B8: 34
A9: SM Gavaskar (INDIA) | B9: 34
A10: DPMD Jayawardene (SL) | B10: 34
A11: AN Cook (ENG) | B11: 33
A12: Grand Total | B12: 380

Sheet Top 10 Half-Century Makers
A1: Row Labels | B1: Sum of 50
A2: SR Tendulkar (INDIA) | B2: 68
A3: S Chanderpaul (WI) | B3: 66
A4: AR Border (AUS) | B4: 63
A5: R Dravid (ICC/INDIA) | B5: 63
A6: RT Ponting (AUS) | B6: 62
A7: JH Kallis (ICC/SA) | B7: 58
A8: AN Cook (ENG) | B8: 57
A9: VVS Laxman (INDIA) | B9: 56
A10: KC Sangakkara (SL) | B10: 52
A11: JE Root (ENG) | B11: 51
A12: Grand Total | B12: 596

Sheet Most Ducks
A1: Row Labels | B1: Sum of 0
A2: SR Waugh (AUS) | B2: 22
A3: MS Atapattu (SL) | B3: 22
A4: MA Atherton (ENG) | B4: 20
A5: Younis Khan (PAK) | B5: 19
A6: ME Waugh (AUS) | B6: 19
A7: Azhar Ali (PAK) | B7: 18
A8: BC Lara (ICC/WI) | B8: 17
A9: RT Ponting (AUS) | B9: 17
A10: MV Boucher (ICC/SA) | B10: 17
A11: V Sehwag (ICC/INDIA) | B11: 16
A12: JH Kallis (ICC/SA) | B12: 16
A13: N Kapil Dev (INDIA) | B13: 16
... A16: Grand Total | B16: 251

Sheet Matches vs Runs
A1: Row Labels | B1: Sum of Mat | C1: Sum of Runs
A2: A Ranatunga (SL) | B2: 93 | C2: 5105
A3: AB de Villiers (SA) | B3: 114 | C3: 8765
A4: AC Gilchrist (AUS) | B4: 96 | C4: 5570
A5: AD Mathews (SL) | B5: 92 | C5: 6338
A6: AJ Stewart (ENG) | B6: 133 | C6: 8463
A7: AJ Strauss (ENG) | B7: 100 | C7: 7037
A8: AN Cook (ENG) | B8: 161 | C8: 12472
A9: AR Border (AUS) | B9: 156 | C9: 11174
A10: Azhar Ali (PAK) | B10: 91 | C10: 6721
A11: BB McCullum (NZ) | B11: 101 | C11: 6453
A12: BC Lara (ICC/WI) | B12: 131 | C12: 11953
A13: CA Pujara (INDIA) | B13: 92 | C13: 6589
... A99: Grand Total | B99: 9937 | C99: 736782

Sheet 100s vs 50s Analysis
A1: Row Labels | B1: Sum of 100 | C1: Sum of 50
A2: SR Tendulkar (INDIA) | B2: 51 | C2: 68
A3: JH Kallis (ICC/SA) | B3: 45 | C3: 58
A4: RT Ponting (AUS) | B4: 41 | C4: 62
A5: KC Sangakkara (SL) | B5: 38 | C5: 52
A6: R Dravid (ICC/INDIA) | B6: 36 | C6: 63
A7: Younis Khan (PAK) | B7: 34 | C7: 33
A8: BC Lara (ICC/WI) | B8: 34 | C8: 48
A9: SM Gavaskar (INDIA) | B9: 34 | C9: 45
A10: DPMD Jayawardene (SL) | B10: 34 | C10: 50
A11: AN Cook (ENG) | B11: 33 | C11: 57
A12: Grand Total | B12: 380 | C12: 536

Sheet KPI
B1: KPI
B3: Total Players | D3: =COUNTA(raw_data!A2:A1001) -> 97
B5: Total Matches | D5: =SUM(raw_data!D2:D1000) -> 9937
B7: Total Runs | D7: =SUM(raw_data!G2:G1000) -> 736782
B9: Total Centuries | D9: =SUM(raw_data!J2:J1000) -> 1997
B11: Total Half Centuries | D11: =SUM(raw_data!K2:K1000) -> 3453
B13: Highest Score | D13: =MAX(raw_data!Q2:Q1000) -> 400

Sheet DashBoard
A1: CRICKET PLAYER PERFORMANCE DASHBOARD
